Traceback (most recent call last):
  File "/smi-slave/manage.py", line 15, in <module>
    execute_from_command_line(sys.argv)
  File "/usr/local/lib/python3.8/site-packages/django/core/management/__init__.py", line 401, in execute_from_command_line
    utility.execute()
  File "/usr/local/lib/python3.8/site-packages/django/core/management/__init__.py", line 395, in execute
    self.fetch_command(subcommand).run_from_argv(self.argv)
  File "/usr/local/lib/python3.8/site-packages/django/core/management/base.py", line 328, in run_from_argv
    self.execute(*args, **cmd_options)
  File "/usr/local/lib/python3.8/site-packages/django/core/management/base.py", line 366, in execute
    self.check()
  File "/usr/local/lib/python3.8/site-packages/django/core/management/base.py", line 392, in check
    all_issues = self._run_checks(
  File "/usr/local/lib/python3.8/site-packages/django/core/management/base.py", line 382, in _run_checks
    return checks.run_checks(**kwargs)
  File "/usr/local/lib/python3.8/site-packages/django/core/checks/registry.py", line 72, in run_checks
    new_errors = check(app_configs=app_configs)
  File "/usr/local/lib/python3.8/site-packages/django/core/checks/urls.py", line 13, in check_url_config
    return check_resolver(resolver)
  File "/usr/local/lib/python3.8/site-packages/django/core/checks/urls.py", line 23, in check_resolver
    return check_method()
  File "/usr/local/lib/python3.8/site-packages/django/urls/resolvers.py", line 407, in check
    for pattern in self.url_patterns:
  File "/usr/local/lib/python3.8/site-packages/django/utils/functional.py", line 48, in __get__
    res = instance.__dict__[self.name] = self.func(instance)
  File "/usr/local/lib/python3.8/site-packages/django/urls/resolvers.py", line 588, in url_patterns
    patterns = getattr(self.urlconf_module, "urlpatterns", self.urlconf_module)
  File "/usr/local/lib/python3.8/site-packages/django/utils/functional.py", line 48, in __get__
    res = instance.__dict__[self.name] = self.func(instance)
  File "/usr/local/lib/python3.8/site-packages/django/urls/resolvers.py", line 581, in urlconf_module
    return import_module(self.urlconf_name)
  File "/usr/local/lib/python3.8/importlib/__init__.py", line 127, in import_module
    return _bootstrap._gcd_import(name[level:], package, level)
  File "<frozen importlib._bootstrap>", line 1014, in _gcd_import
  File "<frozen importlib._bootstrap>", line 991, in _find_and_load
  File "<frozen importlib._bootstrap>", line 975, in _find_and_load_unlocked
  File "<frozen importlib._bootstrap>", line 671, in _load_unlocked
  File "<frozen importlib._bootstrap_external>", line 843, in exec_module
  File "<frozen importlib._bootstrap>", line 219, in _call_with_frames_removed
  File "/smi-slave/smi/urls.py", line 18, in <module>
    path('docs/', include_docs_urls(title='My API title')),
  File "/usr/local/lib/python3.8/site-packages/rest_framework/documentation.py", line 61, in include_docs_urls
    docs_view = get_docs_view(
  File "/usr/local/lib/python3.8/site-packages/rest_framework/documentation.py", line 20, in get_docs_view
    return get_schema_view(
  File "/usr/local/lib/python3.8/site-packages/rest_framework/schemas/__init__.py", line 45, in get_schema_view
    generator = generator_class(
  File "/usr/local/lib/python3.8/site-packages/rest_framework/schemas/coreapi.py", line 120, in __init__
    assert coreapi, '`coreapi` must be installed for schema support.'
AssertionError: `coreapi` must be installed for schema support.
Traceback (most recent call last):
  File "/smi-slave/manage.py", line 15, in <module>
    execute_from_command_line(sys.argv)
  File "/usr/local/lib/python3.8/site-packages/django/core/management/__init__.py", line 401, in execute_from_command_line
    utility.execute()
  File "/usr/local/lib/python3.8/site-packages/django/core/management/__init__.py", line 395, in execute
    self.fetch_command(subcommand).run_from_argv(self.argv)
  File "/usr/local/lib/python3.8/site-packages/django/core/management/base.py", line 328, in run_from_argv
    self.execute(*args, **cmd_options)
  File "/usr/local/lib/python3.8/site-packages/django/core/management/base.py", line 366, in execute
    self.check()
  File "/usr/local/lib/python3.8/site-packages/django/core/management/base.py", line 392, in check
    all_issues = self._run_checks(
  File "/usr/local/lib/python3.8/site-packages/django/core/management/base.py", line 382, in _run_checks
    return checks.run_checks(**kwargs)
  File "/usr/local/lib/python3.8/site-packages/django/core/checks/registry.py", line 72, in run_checks
    new_errors = check(app_configs=app_configs)
  File "/usr/local/lib/python3.8/site-packages/django/core/checks/urls.py", line 13, in check_url_config
    return check_resolver(resolver)
  File "/usr/local/lib/python3.8/site-packages/django/core/checks/urls.py", line 23, in check_resolver
    return check_method()
  File "/usr/local/lib/python3.8/site-packages/django/urls/resolvers.py", line 407, in check
    for pattern in self.url_patterns:
  File "/usr/local/lib/python3.8/site-packages/django/utils/functional.py", line 48, in __get__
    res = instance.__dict__[self.name] = self.func(instance)
  File "/usr/local/lib/python3.8/site-packages/django/urls/resolvers.py", line 588, in url_patterns
    patterns = getattr(self.urlconf_module, "urlpatterns", self.urlconf_module)
  File "/usr/local/lib/python3.8/site-packages/django/utils/functional.py", line 48, in __get__
    res = instance.__dict__[self.name] = self.func(instance)
  File "/usr/local/lib/python3.8/site-packages/django/urls/resolvers.py", line 581, in urlconf_module
    return import_module(self.urlconf_name)
  File "/usr/local/lib/python3.8/importlib/__init__.py", line 127, in import_module
    return _bootstrap._gcd_import(name[level:], package, level)
  File "<frozen importlib._bootstrap>", line 1014, in _gcd_import
  File "<frozen importlib._bootstrap>", line 991, in _find_and_load
  File "<frozen importlib._bootstrap>", line 975, in _find_and_load_unlocked
  File "<frozen importlib._bootstrap>", line 671, in _load_unlocked
  File "<frozen importlib._bootstrap_external>", line 843, in exec_module
  File "<frozen importlib._bootstrap>", line 219, in _call_with_frames_removed
  File "/smi-slave/smi/urls.py", line 18, in <module>
    path('docs/', include_docs_urls(title='My API title')),
  File "/usr/local/lib/python3.8/site-packages/rest_framework/documentation.py", line 61, in include_docs_urls
    docs_view = get_docs_view(
  File "/usr/local/lib/python3.8/site-packages/rest_framework/documentation.py", line 20, in get_docs_view
    return get_schema_view(
  File "/usr/local/lib/python3.8/site-packages/rest_framework/schemas/__init__.py", line 45, in get_schema_view
    generator = generator_class(
  File "/usr/local/lib/python3.8/site-packages/rest_framework/schemas/coreapi.py", line 120, in __init__
    assert coreapi, '`coreapi` must be installed for schema support.'
AssertionError: `coreapi` must be installed for schema support.
Traceback (most recent call last):
  File "/smi-slave/manage.py", line 15, in <module>
    execute_from_command_line(sys.argv)
  File "/usr/local/lib/python3.8/site-packages/django/core/management/__init__.py", line 401, in execute_from_command_line
    utility.execute()
  File "/usr/local/lib/python3.8/site-packages/django/core/management/__init__.py", line 395, in execute
    self.fetch_command(subcommand).run_from_argv(self.argv)
  File "/usr/local/lib/python3.8/site-packages/django/core/management/base.py", line 328, in run_from_argv
    self.execute(*args, **cmd_options)
  File "/usr/local/lib/python3.8/site-packages/django/core/management/base.py", line 366, in execute
    self.check()
  File "/usr/local/lib/python3.8/site-packages/django/core/management/base.py", line 392, in check
    all_issues = self._run_checks(
  File "/usr/local/lib/python3.8/site-packages/django/core/management/base.py", line 382, in _run_checks
    return checks.run_checks(**kwargs)
  File "/usr/local/lib/python3.8/site-packages/django/core/checks/registry.py", line 72, in run_checks
    new_errors = check(app_configs=app_configs)
  File "/usr/local/lib/python3.8/site-packages/django/core/checks/urls.py", line 13, in check_url_config
    return check_resolver(resolver)
  File "/usr/local/lib/python3.8/site-packages/django/core/checks/urls.py", line 23, in check_resolver
    return check_method()
  File "/usr/local/lib/python3.8/site-packages/django/urls/resolvers.py", line 407, in check
    for pattern in self.url_patterns:
  File "/usr/local/lib/python3.8/site-packages/django/utils/functional.py", line 48, in __get__
    res = instance.__dict__[self.name] = self.func(instance)
  File "/usr/local/lib/python3.8/site-packages/django/urls/resolvers.py", line 588, in url_patterns
    patterns = getattr(self.urlconf_module, "urlpatterns", self.urlconf_module)
  File "/usr/local/lib/python3.8/site-packages/django/utils/functional.py", line 48, in __get__
    res = instance.__dict__[self.name] = self.func(instance)
  File "/usr/local/lib/python3.8/site-packages/django/urls/resolvers.py", line 581, in urlconf_module
    return import_module(self.urlconf_name)
  File "/usr/local/lib/python3.8/importlib/__init__.py", line 127, in import_module
    return _bootstrap._gcd_import(name[level:], package, level)
  File "<frozen importlib._bootstrap>", line 1014, in _gcd_import
  File "<frozen importlib._bootstrap>", line 991, in _find_and_load
  File "<frozen importlib._bootstrap>", line 975, in _find_and_load_unlocked
  File "<frozen importlib._bootstrap>", line 671, in _load_unlocked
  File "<frozen importlib._bootstrap_external>", line 843, in exec_module
  File "<frozen importlib._bootstrap>", line 219, in _call_with_frames_removed
  File "/smi-slave/smi/urls.py", line 18, in <module>
    path('docs/', include_docs_urls(title='My API title')),
  File "/usr/local/lib/python3.8/site-packages/rest_framework/documentation.py", line 61, in include_docs_urls
    docs_view = get_docs_view(
  File "/usr/local/lib/python3.8/site-packages/rest_framework/documentation.py", line 20, in get_docs_view
    return get_schema_view(
  File "/usr/local/lib/python3.8/site-packages/rest_framework/schemas/__init__.py", line 45, in get_schema_view
    generator = generator_class(
  File "/usr/local/lib/python3.8/site-packages/rest_framework/schemas/coreapi.py", line 120, in __init__
    assert coreapi, '`coreapi` must be installed for schema support.'
AssertionError: `coreapi` must be installed for schema support.
Traceback (most recent call last):
  File "/smi-slave/manage.py", line 15, in <module>
    execute_from_command_line(sys.argv)
  File "/usr/local/lib/python3.8/site-packages/django/core/management/__init__.py", line 401, in execute_from_command_line
    utility.execute()
  File "/usr/local/lib/python3.8/site-packages/django/core/management/__init__.py", line 395, in execute
    self.fetch_command(subcommand).run_from_argv(self.argv)
  File "/usr/local/lib/python3.8/site-packages/django/core/management/base.py", line 328, in run_from_argv
    self.execute(*args, **cmd_options)
  File "/usr/local/lib/python3.8/site-packages/django/core/management/base.py", line 366, in execute
    self.check()
  File "/usr/local/lib/python3.8/site-packages/django/core/management/base.py", line 392, in check
    all_issues = self._run_checks(
  File "/usr/local/lib/python3.8/site-packages/django/core/management/base.py", line 382, in _run_checks
    return checks.run_checks(**kwargs)
  File "/usr/local/lib/python3.8/site-packages/django/core/checks/registry.py", line 72, in run_checks
    new_errors = check(app_configs=app_configs)
  File "/usr/local/lib/python3.8/site-packages/django/core/checks/urls.py", line 13, in check_url_config
    return check_resolver(resolver)
  File "/usr/local/lib/python3.8/site-packages/django/core/checks/urls.py", line 23, in check_resolver
    return check_method()
  File "/usr/local/lib/python3.8/site-packages/django/urls/resolvers.py", line 407, in check
    for pattern in self.url_patterns:
  File "/usr/local/lib/python3.8/site-packages/django/utils/functional.py", line 48, in __get__
    res = instance.__dict__[self.name] = self.func(instance)
  File "/usr/local/lib/python3.8/site-packages/django/urls/resolvers.py", line 588, in url_patterns
    patterns = getattr(self.urlconf_module, "urlpatterns", self.urlconf_module)
  File "/usr/local/lib/python3.8/site-packages/django/utils/functional.py", line 48, in __get__
    res = instance.__dict__[self.name] = self.func(instance)
  File "/usr/local/lib/python3.8/site-packages/django/urls/resolvers.py", line 581, in urlconf_module
    return import_module(self.urlconf_name)
  File "/usr/local/lib/python3.8/importlib/__init__.py", line 127, in import_module
    return _bootstrap._gcd_import(name[level:], package, level)
  File "<frozen importlib._bootstrap>", line 1014, in _gcd_import
  File "<frozen importlib._bootstrap>", line 991, in _find_and_load
  File "<frozen importlib._bootstrap>", line 975, in _find_and_load_unlocked
  File "<frozen importlib._bootstrap>", line 671, in _load_unlocked
  File "<frozen importlib._bootstrap_external>", line 843, in exec_module
  File "<frozen importlib._bootstrap>", line 219, in _call_with_frames_removed
  File "/smi-slave/smi/urls.py", line 18, in <module>
    path('docs/', include_docs_urls(title='Slave')),
  File "/usr/local/lib/python3.8/site-packages/rest_framework/documentation.py", line 61, in include_docs_urls
    docs_view = get_docs_view(
  File "/usr/local/lib/python3.8/site-packages/rest_framework/documentation.py", line 20, in get_docs_view
    return get_schema_view(
  File "/usr/local/lib/python3.8/site-packages/rest_framework/schemas/__init__.py", line 45, in get_schema_view
    generator = generator_class(
  File "/usr/local/lib/python3.8/site-packages/rest_framework/schemas/coreapi.py", line 120, in __init__
    assert coreapi, '`coreapi` must be installed for schema support.'
AssertionError: `coreapi` must be installed for schema support.
Traceback (most recent call last):
  File "/smi-slave/manage.py", line 15, in <module>
    execute_from_command_line(sys.argv)
  File "/usr/local/lib/python3.8/site-packages/django/core/management/__init__.py", line 401, in execute_from_command_line
    utility.execute()
  File "/usr/local/lib/python3.8/site-packages/django/core/management/__init__.py", line 395, in execute
    self.fetch_command(subcommand).run_from_argv(self.argv)
  File "/usr/local/lib/python3.8/site-packages/django/core/management/base.py", line 328, in run_from_argv
    self.execute(*args, **cmd_options)
  File "/usr/local/lib/python3.8/site-packages/django/core/management/base.py", line 366, in execute
    self.check()
  File "/usr/local/lib/python3.8/site-packages/django/core/management/base.py", line 392, in check
    all_issues = self._run_checks(
  File "/usr/local/lib/python3.8/site-packages/django/core/management/base.py", line 382, in _run_checks
    return checks.run_checks(**kwargs)
  File "/usr/local/lib/python3.8/site-packages/django/core/checks/registry.py", line 72, in run_checks
    new_errors = check(app_configs=app_configs)
  File "/usr/local/lib/python3.8/site-packages/django/core/checks/urls.py", line 13, in check_url_config
    return check_resolver(resolver)
  File "/usr/local/lib/python3.8/site-packages/django/core/checks/urls.py", line 23, in check_resolver
    return check_method()
  File "/usr/local/lib/python3.8/site-packages/django/urls/resolvers.py", line 407, in check
    for pattern in self.url_patterns:
  File "/usr/local/lib/python3.8/site-packages/django/utils/functional.py", line 48, in __get__
    res = instance.__dict__[self.name] = self.func(instance)
  File "/usr/local/lib/python3.8/site-packages/django/urls/resolvers.py", line 588, in url_patterns
    patterns = getattr(self.urlconf_module, "urlpatterns", self.urlconf_module)
  File "/usr/local/lib/python3.8/site-packages/django/utils/functional.py", line 48, in __get__
    res = instance.__dict__[self.name] = self.func(instance)
  File "/usr/local/lib/python3.8/site-packages/django/urls/resolvers.py", line 581, in urlconf_module
    return import_module(self.urlconf_name)
  File "/usr/local/lib/python3.8/importlib/__init__.py", line 127, in import_module
    return _bootstrap._gcd_import(name[level:], package, level)
  File "<frozen importlib._bootstrap>", line 1014, in _gcd_import
  File "<frozen importlib._bootstrap>", line 991, in _find_and_load
  File "<frozen importlib._bootstrap>", line 975, in _find_and_load_unlocked
  File "<frozen importlib._bootstrap>", line 671, in _load_unlocked
  File "<frozen importlib._bootstrap_external>", line 843, in exec_module
  File "<frozen importlib._bootstrap>", line 219, in _call_with_frames_removed
  File "/smi-slave/smi/urls.py", line 18, in <module>
    path('docs/', include_docs_urls(title='Slave')),
  File "/usr/local/lib/python3.8/site-packages/rest_framework/documentation.py", line 61, in include_docs_urls
    docs_view = get_docs_view(
  File "/usr/local/lib/python3.8/site-packages/rest_framework/documentation.py", line 20, in get_docs_view
    return get_schema_view(
  File "/usr/local/lib/python3.8/site-packages/rest_framework/schemas/__init__.py", line 45, in get_schema_view
    generator = generator_class(
  File "/usr/local/lib/python3.8/site-packages/rest_framework/schemas/coreapi.py", line 120, in __init__
    assert coreapi, '`coreapi` must be installed for schema support.'
AssertionError: `coreapi` must be installed for schema support.
Traceback (most recent call last):
  File "/smi-slave/manage.py", line 15, in <module>
    execute_from_command_line(sys.argv)
  File "/usr/local/lib/python3.8/site-packages/django/core/management/__init__.py", line 401, in execute_from_command_line
    utility.execute()
  File "/usr/local/lib/python3.8/site-packages/django/core/management/__init__.py", line 395, in execute
    self.fetch_command(subcommand).run_from_argv(self.argv)
  File "/usr/local/lib/python3.8/site-packages/django/core/management/base.py", line 328, in run_from_argv
    self.execute(*args, **cmd_options)
  File "/usr/local/lib/python3.8/site-packages/django/core/management/base.py", line 366, in execute
    self.check()
  File "/usr/local/lib/python3.8/site-packages/django/core/management/base.py", line 392, in check
    all_issues = self._run_checks(
  File "/usr/local/lib/python3.8/site-packages/django/core/management/base.py", line 382, in _run_checks
    return checks.run_checks(**kwargs)
  File "/usr/local/lib/python3.8/site-packages/django/core/checks/registry.py", line 72, in run_checks
    new_errors = check(app_configs=app_configs)
  File "/usr/local/lib/python3.8/site-packages/django/core/checks/urls.py", line 13, in check_url_config
    return check_resolver(resolver)
  File "/usr/local/lib/python3.8/site-packages/django/core/checks/urls.py", line 23, in check_resolver
    return check_method()
  File "/usr/local/lib/python3.8/site-packages/django/urls/resolvers.py", line 407, in check
    for pattern in self.url_patterns:
  File "/usr/local/lib/python3.8/site-packages/django/utils/functional.py", line 48, in __get__
    res = instance.__dict__[self.name] = self.func(instance)
  File "/usr/local/lib/python3.8/site-packages/django/urls/resolvers.py", line 588, in url_patterns
    patterns = getattr(self.urlconf_module, "urlpatterns", self.urlconf_module)
  File "/usr/local/lib/python3.8/site-packages/django/utils/functional.py", line 48, in __get__
    res = instance.__dict__[self.name] = self.func(instance)
  File "/usr/local/lib/python3.8/site-packages/django/urls/resolvers.py", line 581, in urlconf_module
    return import_module(self.urlconf_name)
  File "/usr/local/lib/python3.8/importlib/__init__.py", line 127, in import_module
    return _bootstrap._gcd_import(name[level:], package, level)
  File "<frozen importlib._bootstrap>", line 1014, in _gcd_import
  File "<frozen importlib._bootstrap>", line 991, in _find_and_load
  File "<frozen importlib._bootstrap>", line 975, in _find_and_load_unlocked
  File "<frozen importlib._bootstrap>", line 671, in _load_unlocked
  File "<frozen importlib._bootstrap_external>", line 843, in exec_module
  File "<frozen importlib._bootstrap>", line 219, in _call_with_frames_removed
  File "/smi-slave/smi/urls.py", line 18, in <module>
    path('docs/', include_docs_urls(title='Slave')),
  File "/usr/local/lib/python3.8/site-packages/rest_framework/documentation.py", line 61, in include_docs_urls
    docs_view = get_docs_view(
  File "/usr/local/lib/python3.8/site-packages/rest_framework/documentation.py", line 20, in get_docs_view
    return get_schema_view(
  File "/usr/local/lib/python3.8/site-packages/rest_framework/schemas/__init__.py", line 45, in get_schema_view
    generator = generator_class(
  File "/usr/local/lib/python3.8/site-packages/rest_framework/schemas/coreapi.py", line 120, in __init__
    assert coreapi, '`coreapi` must be installed for schema support.'
AssertionError: `coreapi` must be installed for schema support.
Traceback (most recent call last):
  File "/smi-slave/manage.py", line 15, in <module>
    execute_from_command_line(sys.argv)
  File "/usr/local/lib/python3.8/site-packages/django/core/management/__init__.py", line 401, in execute_from_command_line
    utility.execute()
  File "/usr/local/lib/python3.8/site-packages/django/core/management/__init__.py", line 395, in execute
    self.fetch_command(subcommand).run_from_argv(self.argv)
  File "/usr/local/lib/python3.8/site-packages/django/core/management/base.py", line 328, in run_from_argv
    self.execute(*args, **cmd_options)
  File "/usr/local/lib/python3.8/site-packages/django/core/management/base.py", line 366, in execute
    self.check()
  File "/usr/local/lib/python3.8/site-packages/django/core/management/base.py", line 392, in check
    all_issues = self._run_checks(
  File "/usr/local/lib/python3.8/site-packages/django/core/management/base.py", line 382, in _run_checks
    return checks.run_checks(**kwargs)
  File "/usr/local/lib/python3.8/site-packages/django/core/checks/registry.py", line 72, in run_checks
    new_errors = check(app_configs=app_configs)
  File "/usr/local/lib/python3.8/site-packages/django/core/checks/urls.py", line 13, in check_url_config
    return check_resolver(resolver)
  File "/usr/local/lib/python3.8/site-packages/django/core/checks/urls.py", line 23, in check_resolver
    return check_method()
  File "/usr/local/lib/python3.8/site-packages/django/urls/resolvers.py", line 407, in check
    for pattern in self.url_patterns:
  File "/usr/local/lib/python3.8/site-packages/django/utils/functional.py", line 48, in __get__
    res = instance.__dict__[self.name] = self.func(instance)
  File "/usr/local/lib/python3.8/site-packages/django/urls/resolvers.py", line 588, in url_patterns
    patterns = getattr(self.urlconf_module, "urlpatterns", self.urlconf_module)
  File "/usr/local/lib/python3.8/site-packages/django/utils/functional.py", line 48, in __get__
    res = instance.__dict__[self.name] = self.func(instance)
  File "/usr/local/lib/python3.8/site-packages/django/urls/resolvers.py", line 581, in urlconf_module
    return import_module(self.urlconf_name)
  File "/usr/local/lib/python3.8/importlib/__init__.py", line 127, in import_module
    return _bootstrap._gcd_import(name[level:], package, level)
  File "<frozen importlib._bootstrap>", line 1014, in _gcd_import
  File "<frozen importlib._bootstrap>", line 991, in _find_and_load
  File "<frozen importlib._bootstrap>", line 975, in _find_and_load_unlocked
  File "<frozen importlib._bootstrap>", line 671, in _load_unlocked
  File "<frozen importlib._bootstrap_external>", line 843, in exec_module
  File "<frozen importlib._bootstrap>", line 219, in _call_with_frames_removed
  File "/smi-slave/smi/urls.py", line 18, in <module>
    path('docs/', include_docs_urls(title='Slave')),
  File "/usr/local/lib/python3.8/site-packages/rest_framework/documentation.py", line 61, in include_docs_urls
    docs_view = get_docs_view(
  File "/usr/local/lib/python3.8/site-packages/rest_framework/documentation.py", line 20, in get_docs_view
    return get_schema_view(
  File "/usr/local/lib/python3.8/site-packages/rest_framework/schemas/__init__.py", line 45, in get_schema_view
    generator = generator_class(
  File "/usr/local/lib/python3.8/site-packages/rest_framework/schemas/coreapi.py", line 120, in __init__
    assert coreapi, '`coreapi` must be installed for schema support.'
AssertionError: `coreapi` must be installed for schema support.
Traceback (most recent call last):
  File "/smi-slave/manage.py", line 15, in <module>
    execute_from_command_line(sys.argv)
  File "/usr/local/lib/python3.8/site-packages/django/core/management/__init__.py", line 401, in execute_from_command_line
    utility.execute()
  File "/usr/local/lib/python3.8/site-packages/django/core/management/__init__.py", line 395, in execute
    self.fetch_command(subcommand).run_from_argv(self.argv)
  File "/usr/local/lib/python3.8/site-packages/django/core/management/base.py", line 328, in run_from_argv
    self.execute(*args, **cmd_options)
  File "/usr/local/lib/python3.8/site-packages/django/core/management/base.py", line 366, in execute
    self.check()
  File "/usr/local/lib/python3.8/site-packages/django/core/management/base.py", line 392, in check
    all_issues = self._run_checks(
  File "/usr/local/lib/python3.8/site-packages/django/core/management/base.py", line 382, in _run_checks
    return checks.run_checks(**kwargs)
  File "/usr/local/lib/python3.8/site-packages/django/core/checks/registry.py", line 72, in run_checks
    new_errors = check(app_configs=app_configs)
  File "/usr/local/lib/python3.8/site-packages/django/core/checks/urls.py", line 13, in check_url_config
    return check_resolver(resolver)
  File "/usr/local/lib/python3.8/site-packages/django/core/checks/urls.py", line 23, in check_resolver
    return check_method()
  File "/usr/local/lib/python3.8/site-packages/django/urls/resolvers.py", line 407, in check
    for pattern in self.url_patterns:
  File "/usr/local/lib/python3.8/site-packages/django/utils/functional.py", line 48, in __get__
    res = instance.__dict__[self.name] = self.func(instance)
  File "/usr/local/lib/python3.8/site-packages/django/urls/resolvers.py", line 588, in url_patterns
    patterns = getattr(self.urlconf_module, "urlpatterns", self.urlconf_module)
  File "/usr/local/lib/python3.8/site-packages/django/utils/functional.py", line 48, in __get__
    res = instance.__dict__[self.name] = self.func(instance)
  File "/usr/local/lib/python3.8/site-packages/django/urls/resolvers.py", line 581, in urlconf_module
    return import_module(self.urlconf_name)
  File "/usr/local/lib/python3.8/importlib/__init__.py", line 127, in import_module
    return _bootstrap._gcd_import(name[level:], package, level)
  File "<frozen importlib._bootstrap>", line 1014, in _gcd_import
  File "<frozen importlib._bootstrap>", line 991, in _find_and_load
  File "<frozen importlib._bootstrap>", line 975, in _find_and_load_unlocked
  File "<frozen importlib._bootstrap>", line 671, in _load_unlocked
  File "<frozen importlib._bootstrap_external>", line 843, in exec_module
  File "<frozen importlib._bootstrap>", line 219, in _call_with_frames_removed
  File "/smi-slave/smi/urls.py", line 18, in <module>
    path('docs/', include_docs_urls(title='Slave')),
  File "/usr/local/lib/python3.8/site-packages/rest_framework/documentation.py", line 61, in include_docs_urls
    docs_view = get_docs_view(
  File "/usr/local/lib/python3.8/site-packages/rest_framework/documentation.py", line 20, in get_docs_view
    return get_schema_view(
  File "/usr/local/lib/python3.8/site-packages/rest_framework/schemas/__init__.py", line 45, in get_schema_view
    generator = generator_class(
  File "/usr/local/lib/python3.8/site-packages/rest_framework/schemas/coreapi.py", line 120, in __init__
    assert coreapi, '`coreapi` must be installed for schema support.'
AssertionError: `coreapi` must be installed for schema support.
Traceback (most recent call last):
  File "/smi-slave/manage.py", line 15, in <module>
    execute_from_command_line(sys.argv)
  File "/usr/local/lib/python3.8/site-packages/django/core/management/__init__.py", line 401, in execute_from_command_line
    utility.execute()
  File "/usr/local/lib/python3.8/site-packages/django/core/management/__init__.py", line 395, in execute
    self.fetch_command(subcommand).run_from_argv(self.argv)
  File "/usr/local/lib/python3.8/site-packages/django/core/management/base.py", line 328, in run_from_argv
    self.execute(*args, **cmd_options)
  File "/usr/local/lib/python3.8/site-packages/django/core/management/base.py", line 366, in execute
    self.check()
  File "/usr/local/lib/python3.8/site-packages/django/core/management/base.py", line 392, in check
    all_issues = self._run_checks(
  File "/usr/local/lib/python3.8/site-packages/django/core/management/base.py", line 382, in _run_checks
    return checks.run_checks(**kwargs)
  File "/usr/local/lib/python3.8/site-packages/django/core/checks/registry.py", line 72, in run_checks
    new_errors = check(app_configs=app_configs)
  File "/usr/local/lib/python3.8/site-packages/django/core/checks/urls.py", line 13, in check_url_config
    return check_resolver(resolver)
  File "/usr/local/lib/python3.8/site-packages/django/core/checks/urls.py", line 23, in check_resolver
    return check_method()
  File "/usr/local/lib/python3.8/site-packages/django/urls/resolvers.py", line 407, in check
    for pattern in self.url_patterns:
  File "/usr/local/lib/python3.8/site-packages/django/utils/functional.py", line 48, in __get__
    res = instance.__dict__[self.name] = self.func(instance)
  File "/usr/local/lib/python3.8/site-packages/django/urls/resolvers.py", line 588, in url_patterns
    patterns = getattr(self.urlconf_module, "urlpatterns", self.urlconf_module)
  File "/usr/local/lib/python3.8/site-packages/django/utils/functional.py", line 48, in __get__
    res = instance.__dict__[self.name] = self.func(instance)
  File "/usr/local/lib/python3.8/site-packages/django/urls/resolvers.py", line 581, in urlconf_module
    return import_module(self.urlconf_name)
  File "/usr/local/lib/python3.8/importlib/__init__.py", line 127, in import_module
    return _bootstrap._gcd_import(name[level:], package, level)
  File "<frozen importlib._bootstrap>", line 1014, in _gcd_import
  File "<frozen importlib._bootstrap>", line 991, in _find_and_load
  File "<frozen importlib._bootstrap>", line 975, in _find_and_load_unlocked
  File "<frozen importlib._bootstrap>", line 671, in _load_unlocked
  File "<frozen importlib._bootstrap_external>", line 843, in exec_module
  File "<frozen importlib._bootstrap>", line 219, in _call_with_frames_removed
  File "/smi-slave/smi/urls.py", line 18, in <module>
    path('docs/', include_docs_urls(title='Slave')),
  File "/usr/local/lib/python3.8/site-packages/rest_framework/documentation.py", line 61, in include_docs_urls
    docs_view = get_docs_view(
  File "/usr/local/lib/python3.8/site-packages/rest_framework/documentation.py", line 20, in get_docs_view
    return get_schema_view(
  File "/usr/local/lib/python3.8/site-packages/rest_framework/schemas/__init__.py", line 45, in get_schema_view
    generator = generator_class(
  File "/usr/local/lib/python3.8/site-packages/rest_framework/schemas/coreapi.py", line 120, in __init__
    assert coreapi, '`coreapi` must be installed for schema support.'
AssertionError: `coreapi` must be installed for schema support.
Traceback (most recent call last):
  File "/smi-slave/manage.py", line 15, in <module>
    execute_from_command_line(sys.argv)
  File "/usr/local/lib/python3.8/site-packages/django/core/management/__init__.py", line 401, in execute_from_command_line
    utility.execute()
  File "/usr/local/lib/python3.8/site-packages/django/core/management/__init__.py", line 395, in execute
    self.fetch_command(subcommand).run_from_argv(self.argv)
  File "/usr/local/lib/python3.8/site-packages/django/core/management/base.py", line 328, in run_from_argv
    self.execute(*args, **cmd_options)
  File "/usr/local/lib/python3.8/site-packages/django/core/management/base.py", line 366, in execute
    self.check()
  File "/usr/local/lib/python3.8/site-packages/django/core/management/base.py", line 392, in check
    all_issues = self._run_checks(
  File "/usr/local/lib/python3.8/site-packages/django/core/management/base.py", line 382, in _run_checks
    return checks.run_checks(**kwargs)
  File "/usr/local/lib/python3.8/site-packages/django/core/checks/registry.py", line 72, in run_checks
    new_errors = check(app_configs=app_configs)
  File "/usr/local/lib/python3.8/site-packages/django/core/checks/urls.py", line 13, in check_url_config
    return check_resolver(resolver)
  File "/usr/local/lib/python3.8/site-packages/django/core/checks/urls.py", line 23, in check_resolver
    return check_method()
  File "/usr/local/lib/python3.8/site-packages/django/urls/resolvers.py", line 407, in check
    for pattern in self.url_patterns:
  File "/usr/local/lib/python3.8/site-packages/django/utils/functional.py", line 48, in __get__
    res = instance.__dict__[self.name] = self.func(instance)
  File "/usr/local/lib/python3.8/site-packages/django/urls/resolvers.py", line 588, in url_patterns
    patterns = getattr(self.urlconf_module, "urlpatterns", self.urlconf_module)
  File "/usr/local/lib/python3.8/site-packages/django/utils/functional.py", line 48, in __get__
    res = instance.__dict__[self.name] = self.func(instance)
  File "/usr/local/lib/python3.8/site-packages/django/urls/resolvers.py", line 581, in urlconf_module
    return import_module(self.urlconf_name)
  File "/usr/local/lib/python3.8/importlib/__init__.py", line 127, in import_module
    return _bootstrap._gcd_import(name[level:], package, level)
  File "<frozen importlib._bootstrap>", line 1014, in _gcd_import
  File "<frozen importlib._bootstrap>", line 991, in _find_and_load
  File "<frozen importlib._bootstrap>", line 975, in _find_and_load_unlocked
  File "<frozen importlib._bootstrap>", line 671, in _load_unlocked
  File "<frozen importlib._bootstrap_external>", line 843, in exec_module
  File "<frozen importlib._bootstrap>", line 219, in _call_with_frames_removed
  File "/smi-slave/smi/urls.py", line 18, in <module>
    path('docs/', include_docs_urls(title='Slave')),
  File "/usr/local/lib/python3.8/site-packages/rest_framework/documentation.py", line 61, in include_docs_urls
    docs_view = get_docs_view(
  File "/usr/local/lib/python3.8/site-packages/rest_framework/documentation.py", line 20, in get_docs_view
    return get_schema_view(
  File "/usr/local/lib/python3.8/site-packages/rest_framework/schemas/__init__.py", line 45, in get_schema_view
    generator = generator_class(
  File "/usr/local/lib/python3.8/site-packages/rest_framework/schemas/coreapi.py", line 120, in __init__
    assert coreapi, '`coreapi` must be installed for schema support.'
AssertionError: `coreapi` must be installed for schema support.
